[ 2024-12-09 19:02:35,646 ] werkzeug - INFO - [31m[1mWARNING: This is a development server. Do not use it in a production deployment. Use a production WSGI server instead.[0m
 * Running on all addresses (0.0.0.0)
 * Running on http://127.0.0.1:8080
 * Running on http://172.16.10.186:8080
[ 2024-12-09 19:02:35,646 ] werkzeug - INFO - [33mPress CTRL+C to quit[0m
[ 2024-12-09 19:02:36,550 ] werkzeug - INFO - 127.0.0.1 - - [09/Dec/2024 19:02:36] "GET / HTTP/1.1" 200 -
[ 2024-12-09 19:02:38,718 ] root - INFO - Updated DATA_DOWNLOAD_URL to: https://drive.google.com/file/d/1ECfl3dtYyfivY8kYPq7RHUBTjC-2vf61/view?usp=share_link
[ 2024-12-09 19:02:38,719 ] root - INFO - Entered the start_data_ingestion method of TrainPipeline class
[ 2024-12-09 19:02:38,720 ] root - INFO - Getting the data from URL
[ 2024-12-09 19:02:38,722 ] root - INFO - Entered initiate_data_ingestion method of Data_Ingestion class
[ 2024-12-09 19:02:38,724 ] root - INFO - Downloading data from https://drive.google.com/file/d/1ECfl3dtYyfivY8kYPq7RHUBTjC-2vf61/view?usp=share_link into file artifacts\data_ingestion\data.zip
[ 2024-12-09 19:03:03,384 ] root - ERROR - Error during training: Error occurred python script name [E:\New\main_yolo_v5\End-to-end-Waste-Detection-Using-Yolo-v5-main\wasteDetection\pipeline\training_pipeline.py] line number [98] error message [Error occurred python script name [E:\New\main_yolo_v5\End-to-end-Waste-Detection-Using-Yolo-v5-main\wasteDetection\pipeline\training_pipeline.py] line number [37] error message [Error occurred python script name [E:\New\main_yolo_v5\End-to-end-Waste-Detection-Using-Yolo-v5-main\wasteDetection\components\data_ingestion.py] line number [72] error message [Error occurred python script name [E:\New\main_yolo_v5\End-to-end-Waste-Detection-Using-Yolo-v5-main\wasteDetection\components\data_ingestion.py] line number [37] error message [HTTPSConnectionPool(host='doc-00-ag-docs.googleusercontent.com', port=443): Max retries exceeded with url: /docs/securesc/ha0ro937gcuc7l7deffksulhg5h7mbp1/2k29gl0ph84p88v9g00dsvte0efh3b35/1733751150000/16851312232179065356/*/1ECfl3dtYyfivY8kYPq7RHUBTjC-2vf61?uuid=d44d9766-6eee-4c32-b21a-e820b3dcab5c (Caused by ConnectTimeoutError(<urllib3.connection.HTTPSConnection object at 0x000002ADA38FEB50>, 'Connection to doc-00-ag-docs.googleusercontent.com timed out. (connect timeout=None)'))]]]]
[ 2024-12-09 19:03:03,385 ] werkzeug - INFO - 127.0.0.1 - - [09/Dec/2024 19:03:03] "[35m[1mPOST /train HTTP/1.1[0m" 500 -
[ 2024-12-09 19:03:37,223 ] root - INFO - Updated DATA_DOWNLOAD_URL to: https://drive.google.com/file/d/1ECfl3dtYyfivY8kYPq7RHUBTjC-2vf61/view?usp=share_link
[ 2024-12-09 19:03:37,224 ] root - INFO - Entered the start_data_ingestion method of TrainPipeline class
[ 2024-12-09 19:03:37,224 ] root - INFO - Getting the data from URL
[ 2024-12-09 19:03:37,224 ] root - INFO - Entered initiate_data_ingestion method of Data_Ingestion class
[ 2024-12-09 19:03:37,225 ] root - INFO - Downloading data from https://drive.google.com/file/d/1ECfl3dtYyfivY8kYPq7RHUBTjC-2vf61/view?usp=share_link into file artifacts\data_ingestion\data.zip
[ 2024-12-09 19:04:01,583 ] root - ERROR - Error during training: Error occurred python script name [E:\New\main_yolo_v5\End-to-end-Waste-Detection-Using-Yolo-v5-main\wasteDetection\pipeline\training_pipeline.py] line number [98] error message [Error occurred python script name [E:\New\main_yolo_v5\End-to-end-Waste-Detection-Using-Yolo-v5-main\wasteDetection\pipeline\training_pipeline.py] line number [37] error message [Error occurred python script name [E:\New\main_yolo_v5\End-to-end-Waste-Detection-Using-Yolo-v5-main\wasteDetection\components\data_ingestion.py] line number [72] error message [Error occurred python script name [E:\New\main_yolo_v5\End-to-end-Waste-Detection-Using-Yolo-v5-main\wasteDetection\components\data_ingestion.py] line number [37] error message [HTTPSConnectionPool(host='doc-00-ag-docs.googleusercontent.com', port=443): Max retries exceeded with url: /docs/securesc/ha0ro937gcuc7l7deffksulhg5h7mbp1/2k29gl0ph84p88v9g00dsvte0efh3b35/1733751150000/16851312232179065356/*/1ECfl3dtYyfivY8kYPq7RHUBTjC-2vf61?uuid=eead9e5e-c9a2-4b51-9d0e-49b83b014d4d (Caused by ConnectTimeoutError(<urllib3.connection.HTTPSConnection object at 0x000002ADA3914BD0>, 'Connection to doc-00-ag-docs.googleusercontent.com timed out. (connect timeout=None)'))]]]]
[ 2024-12-09 19:04:01,585 ] werkzeug - INFO - 127.0.0.1 - - [09/Dec/2024 19:04:01] "[35m[1mPOST /train HTTP/1.1[0m" 500 -
